Workbook

Sheet 貼付シート
B1: ================================================================================
B2: 取引明細一覧表 出力日：2024/06/30 PAGE: 1
B3: ================================================================================
B4: 部署CD 従業員CD 氏名 取引日 取引先名 金額 摘要
B5: ────────────────────────────────────────────────────────────────────────────────────
B6: 【001000 総務部 】
A7: =IF(MIDB(B7,11,1)="-",ROW(B7),"") -> 7 | B7: 001000 EMP-00101 佐藤 一郎 2024/06/01 株式会社北都商事 125000 事務用品購入
A8: =IF(MIDB(B8,11,1)="-",ROW(B8),"") -> 8 | B8: 001000 EMP-00101 佐藤 一郎 2024/06/05 有限会社南海物産 48000 消耗品補充
A9: =IF(MIDB(B9,11,1)="-",ROW(B9),"") -> 9 | B9: 001000 EMP-00102 鈴木 花子 2024/06/03 合同会社東西サービス 72000 清掃業務委託
A10: =IF(MIDB(B10,11,1)="-",ROW(B10),"") -> 10 | B10: 001000 EMP-00102 鈴木 花子 2024/06/10 株式会社北都商事 33500 コピー用紙発注
A11: =IF(MIDB(B11,11,1)="-",ROW(B11),"") -> 11 | B11: 001000 EMP-00102 鈴木 花子 2024/06/18 個人事業主田中建設 185000 修繕工事代金
A12: =IF(MIDB(B12,11,1)="-",ROW(B12),"") -> 12 | B12: 001000 EMP-00103 高橋 健太 2024/06/07 株式会社中央システム 96000 PC保守契約
A13: =IF(MIDB(B13,11,1)="-",ROW(B13),"") -> 13 | B13: 001000 EMP-00103 高橋 健太 2024/06/12 合同会社東西サービス 15000 名刺印刷
A14: =IF(MIDB(B14,11,1)="-",ROW(B14),"") -> 14 | B14: 001000 EMP-00103 高橋 健太 2024/06/20 有限会社南海物産 62000 備品購入
A15: =IF(MIDB(B15,11,1)="-",ROW(B15),"") -> 15 | B15: 001000 EMP-00104 渡辺 美咲 2024/06/08 株式会社北都商事 27500 封筒印刷
A16: =IF(MIDB(B16,11,1)="-",ROW(B16),"") -> 16 | B16: 001000 EMP-00104 渡辺 美咲 2024/06/15 株式会社中央システム 110000 サーバー保守
A17: =IF(MIDB(B17,11,1)="-",ROW(B17),"") -> 17 | B17: 001000 EMP-00104 渡辺 美咲 2024/06/22 有限会社南海物産 44000 衛生用品購入
A18: =IF(MIDB(B18,11,1)="-",ROW(B18),"") -> 18 | B18: 001000 EMP-00105 伊藤 大輔 2024/06/11 個人事業主田中建設 230000 空調設備点検
... A22: =IF(MIDB(B22,11,1)="-",ROW(B22),"") | B22: 小計： 1125500
A23: =IF(MIDB(B23,11,1)="-",ROW(B23),"")
A24: =IF(MIDB(B24,11,1)="-",ROW(B24),"") | B24: ================================================================================
A25: =IF(MIDB(B25,11,1)="-",ROW(B25),"") | B25: 取引明細一覧表 出力日：2024/06/30 PAGE: 2
A26: =IF(MIDB(B26,11,1)="-",ROW(B26),"") | B26: ================================================================================
A27: =IF(MIDB(B27,11,1)="-",ROW(B27),"") | B27: 部署CD 従業員CD 氏名 取引日 取引先名 金額 摘要
A28: =IF(MIDB(B28,11,1)="-",ROW(B28),"") | B28: ────────────────────────────────────────────────────────────────────────────────────
A29: =IF(MIDB(B29,11,1)="-",ROW(B29),"") | B29: 【002000 営業第一課 】
A30: =IF(MIDB(B30,11,1)="-",ROW(B30),"") -> 30 | B30: 002000 EMP-00201 中村 翔太 2024/06/02 株式会社西日本工業 340000 製品納品代金
A31: =IF(MIDB(B31,11,1)="-",ROW(B31),"") -> 31 | B31: 002000 EMP-00201 中村 翔太 2024/06/09 有限会社丸山製作所 187000 部品調達費
A32: =IF(MIDB(B32,11,1)="-",ROW(B32),"") -> 32 | B32: 002000 EMP-00201 中村 翔太 2024/06/16 株式会社大和運輸 55000 配送料
A33: =IF(MIDB(B33,11,1)="-",ROW(B33),"") -> 33 | B33: 002000 EMP-00202 小林 真由美 2024/06/04 合同会社グローバル通商 420000 輸入代行手数料
A34: =IF(MIDB(B34,11,1)="-",ROW(B34),"") -> 34 | B34: 002000 EMP-00202 小林 真由美 2024/06/13 株式会社西日本工業 215000 金型製作費
A35: =IF(MIDB(B35,11,1)="-",ROW(B35),"") -> 35 | B35: 002000 EMP-00202 小林 真由美 2024/06/19 有限会社丸山製作所 78000 試作品費用
... A44: =IF(MIDB(B44,11,1)="-",ROW(B44),"") | B44: 小計： 2446000
A45: =IF(MIDB(B45,11,1)="-",ROW(B45),"")
A46: =IF(MIDB(B46,11,1)="-",ROW(B46),"") | B46: ================================================================================
A47: =IF(MIDB(B47,11,1)="-",ROW(B47),"") | B47: 取引明細一覧表 出力日：2024/06/30 PAGE: 3
A48: =IF(MIDB(B48,11,1)="-",ROW(B48),"") | B48: ================================================================================
A49: =IF(MIDB(B49,11,1)="-",ROW(B49),"") | B49: 部署CD 従業員CD 氏名 取引日 取引先名 金額 摘要
A50: =IF(MIDB(B50,11,1)="-",ROW(B50),"") | B50: ────────────────────────────────────────────────────────────────────────────────────
A51: =IF(MIDB(B51,11,1)="-",ROW(B51),"") | B51: 【003000 営業第二課 】
...

Sheet 抽出シート
B1: 番号 | C1: 部署CD | D1: 従業員CD | E1: 氏名 | F1: 取引日 | G1: 取引先名 | H1: 金額 | I1: 適用
A2: {=IFERROR(INDEX(貼付シート!$B$1:$B$10000,SMALL(貼付シート!$A$1:$A$10000,B2)),"")} -> 001000 EMP-00101 佐藤 一郎 2024/06/01 株式会社北都商事 125000 事務用品購入 | B2: 1 | C2: =MIDB(A2,1,6) -> 001000 | D2: =MIDB(A2,8,9) -> EMP-00101 | E2: =TRIM(MIDB(A2,18,23)) -> 佐藤 一郎 | F2: =MIDB(A2,41,10) -> 2024/06/01 | G2: =TRIM(MIDB(A2,52,35)) -> 株式会社北都商事 | H2: =VALUE(TRIM(MIDB(A2,85,10))) -> 125000 | I2: =TRIM(MIDB(A2,96,25)) -> 事務用品購入
A3: {=IFERROR(INDEX(貼付シート!$B$1:$B$10000,SMALL(貼付シート!$A$1:$A$10000,B3)),"")} -> 001000 EMP-00101 佐藤 一郎 2024/06/05 有限会社南海物産 48000 消耗品補充 | B3: 2 | C3: =MIDB(A3,1,6) -> 001000 | D3: =MIDB(A3,8,9) -> EMP-00101 | E3: =TRIM(MIDB(A3,18,23)) -> 佐藤 一郎 | F3: =MIDB(A3,41,10) -> 2024/06/05 | G3: =TRIM(MIDB(A3,52,35)) -> 有限会社南海物産 | H3: =VALUE(TRIM(MIDB(A3,85,10))) -> 48000 | I3: =TRIM(MIDB(A3,96,25)) -> 消耗品補充
A4: {=IFERROR(INDEX(貼付シート!$B$1:$B$10000,SMALL(貼付シート!$A$1:$A$10000,B4)),"")} -> 001000 EMP-00102 鈴木 花子 2024/06/03 合同会社東西サービス 72000 清掃業務委託 | B4: 3 | C4: =MIDB(A4,1,6) -> 001000 | D4: =MIDB(A4,8,9) -> EMP-00102 | E4: =TRIM(MIDB(A4,18,23)) -> 鈴木 花子 | F4: =MIDB(A4,41,10) -> 2024/06/03 | G4: =TRIM(MIDB(A4,52,35)) -> 合同会社東西サービス | H4: =VALUE(TRIM(MIDB(A4,85,10))) -> 72000 | I4: =TRIM(MIDB(A4,96,25)) -> 清掃業務委託
A5: {=IFERROR(INDEX(貼付シート!$B$1:$B$10000,SMALL(貼付シート!$A$1:$A$10000,B5)),"")} -> 001000 EMP-00102 鈴木 花子 2024/06/10 株式会社北都商事 33500 コピー用紙発注 | B5: 4 | C5: =MIDB(A5,1,6) -> 001000 | D5: =MIDB(A5,8,9) -> EMP-00102 | E5: =TRIM(MIDB(A5,18,23)) -> 鈴木 花子 | F5: =MIDB(A5,41,10) -> 2024/06/10 | G5: =TRIM(MIDB(A5,52,35)) -> 株式会社北都商事 | H5: =VALUE(TRIM(MIDB(A5,85,10))) -> 33500 | I5: =TRIM(MIDB(A5,96,25)) -> コピー用紙発注
A6: {=IFERROR(INDEX(貼付シート!$B$1:$B$10000,SMALL(貼付シート!$A$1:$A$10000,B6)),"")} -> 001000 EMP-00102 鈴木 花子 2024/06/18 個人事業主田中建設 185000 修繕工事代金 | B6: 5 | C6: =MIDB(A6,1,6) -> 001000 | D6: =MIDB(A6,8,9) -> EMP-00102 | E6: =TRIM(MIDB(A6,18,23)) -> 鈴木 花子 | F6: =MIDB(A6,41,10) -> 2024/06/18 | G6: =TRIM(MIDB(A6,52,35)) -> 個人事業主田中建設 | H6: =VALUE(TRIM(MIDB(A6,85,10))) -> 185000 | I6: =TRIM(MIDB(A6,96,25)) -> 修繕工事代金
A7: {=IFERROR(INDEX(貼付シート!$B$1:$B$10000,SMALL(貼付シート!$A$1:$A$10000,B7)),"")} -> 001000 EMP-00103 高橋 健太 2024/06/07 株式会社中央システム 96000 PC保守契約 | B7: 6 | C7: =MIDB(A7,1,6) -> 001000 | D7: =MIDB(A7,8,9) -> EMP-00103 | E7: =TRIM(MIDB(A7,18,23)) -> 高橋 健太 | F7: =MIDB(A7,41,10) -> 2024/06/07 | G7: =TRIM(MIDB(A7,52,35)) -> 株式会社中央システム | H7: =VALUE(TRIM(MIDB(A7,85,10))) -> 96000 | I7: =TRIM(MIDB(A7,96,25)) -> PC保守契約
A8: {=IFERROR(INDEX(貼付シート!$B$1:$B$10000,SMALL(貼付シート!$A$1:$A$10000,B8)),"")} -> 001000 EMP-00103 高橋 健太 2024/06/12 合同会社東西サービス 15000 名刺印刷 | B8: 7 | C8: =MIDB(A8,1,6) -> 001000 | D8: =MIDB(A8,8,9) -> EMP-00103 | E8: =TRIM(MIDB(A8,18,23)) -> 高橋 健太 | F8: =MIDB(A8,41,10) -> 2024/06/12 | G8: =TRIM(MIDB(A8,52,35)) -> 合同会社東西サービス | H8: =VALUE(TRIM(MIDB(A8,85,10))) -> 15000 | I8: =TRIM(MIDB(A8,96,25)) -> 名刺印刷
A9: {=IFERROR(INDEX(貼付シート!$B$1:$B$10000,SMALL(貼付シート!$A$1:$A$10000,B9)),"")} -> 001000 EMP-00103 高橋 健太 2024/06/20 有限会社南海物産 62000 備品購入 | B9: 8 | C9: =MIDB(A9,1,6) -> 001000 | D9: =MIDB(A9,8,9) -> EMP-00103 | E9: =TRIM(MIDB(A9,18,23)) -> 高橋 健太 | F9: =MIDB(A9,41,10) -> 2024/06/20 | G9: =TRIM(MIDB(A9,52,35)) -> 有限会社南海物産 | H9: =VALUE(TRIM(MIDB(A9,85,10))) -> 62000 | I9: =TRIM(MIDB(A9,96,25)) -> 備品購入
A10: {=IFERROR(INDEX(貼付シート!$B$1:$B$10000,SMALL(貼付シート!$A$1:$A$10000,B10)),"")} -> 001000 EMP-00104 渡辺 美咲 2024/06/08 株式会社北都商事 27500 封筒印刷 | B10: 9 | C10: =MIDB(A10,1,6) -> 001000 | D10: =MIDB(A10,8,9) -> EMP-00104 | E10: =TRIM(MIDB(A10,18,23)) -> 渡辺 美咲 | F10: =MIDB(A10,41,10) -> 2024/06/08 | G10: =TRIM(MIDB(A10,52,35)) -> 株式会社北都商事 | H10: =VALUE(TRIM(MIDB(A10,85,10))) -> 27500 | I10: =TRIM(MIDB(A10,96,25)) -> 封筒印刷
A11: {=IFERROR(INDEX(貼付シート!$B$1:$B$10000,SMALL(貼付シート!$A$1:$A$10000,B11)),"")} -> 001000 EMP-00104 渡辺 美咲 2024/06/15 株式会社中央システム 110000 サーバー保守 | B11: 10 | C11: =MIDB(A11,1,6) -> 001000 | D11: =MIDB(A11,8,9) -> EMP-00104 | E11: =TRIM(MIDB(A11,18,23)) -> 渡辺 美咲 | F11: =MIDB(A11,41,10) -> 2024/06/15 | G11: =TRIM(MIDB(A11,52,35)) -> 株式会社中央システム | H11: =VALUE(TRIM(MIDB(A11,85,10))) -> 110000 | I11: =TRIM(MIDB(A11,96,25)) -> サーバー保守
A12: {=IFERROR(INDEX(貼付シート!$B$1:$B$10000,SMALL(貼付シート!$A$1:$A$10000,B12)),"")} -> 001000 EMP-00104 渡辺 美咲 2024/06/22 有限会社南海物産 44000 衛生用品購入 | B12: 11 | C12: =MIDB(A12,1,6) -> 001000 | D12: =MIDB(A12,8,9) -> EMP-00104 | E12: =TRIM(MIDB(A12,18,23)) -> 渡辺 美咲 | F12: =MIDB(A12,41,10) -> 2024/06/22 | G12: =TRIM(MIDB(A12,52,35)) -> 有限会社南海物産 | H12: =VALUE(TRIM(MIDB(A12,85,10))) -> 44000 | I12: =TRIM(MIDB(A12,96,25)) -> 衛生用品購入
A13: {=IFERROR(INDEX(貼付シート!$B$1:$B$10000,SMALL(貼付シート!$A$1:$A$10000,B13)),"")} -> 001000 EMP-00105 伊藤 大輔 2024/06/11 個人事業主田中建設 230000 空調設備点検 | B13: 12 | C13: =MIDB(A13,1,6) -> 001000 | D13: =MIDB(A13,8,9) -> EMP-00105 | E13: =TRIM(MIDB(A13,18,23)) -> 伊藤 大輔 | F13: =MIDB(A13,41,10) -> 2024/06/11 | G13: =TRIM(MIDB(A13,52,35)) -> 個人事業主田中建設 | H13: =VALUE(TRIM(MIDB(A13,85,10))) -> 230000 | I13: =TRIM(MIDB(A13,96,25)) -> 空調設備点検
... A200: {=IFERROR(INDEX(貼付シート!$B$1:$B$10000,SMALL(貼付シート!$A$1:$A$10000,B200)),"")} | B200: 199 | C200: =MIDB(A200,1,6) | D200: =MIDB(A200,8,9) | E200: =TRIM(MIDB(A200,18,23)) | F200: =MIDB(A200,41,10) | G200: =TRIM(MIDB(A200,52,35)) | H200: =VALUE(TRIM(MIDB(A200,85,10))) -> #VALUE! | I200: =TRIM(MIDB(A200,96,25))

Sheet 手順書
A1: 固定長テキスト整形テンプレート ― カスタマイズ手順書
A3: ■ このテンプレートの仕組み
A5: 処理の流れ
A6: ① 貼付シートのB1セルに固定長テキストをそのまま貼り付ける
A7: ② 判定列（貼付シートA列）でデータ行だけに行番号の目印が付く（不要行は空欄になる）
A8: ③ 抽出シートが目印の付いた行だけを取り込む
A9: ④ 抽出シートのMIDB関数でバイト位置ごとに項目を切り出す
A10: ⑤ TRIM関数で切り出し後の余分なスペースを除去する
A12: ※ この2段階構成によりMIDB関数はデータ行の数だけで済み、数式が最小限になります
A15: ■ 使用している関数の説明
A17: 【MIDB関数】
A18: 書式：MIDB(文字列, 開始位置, バイト数)
... A211: ご自身の環境に合わせて置き換えていただいても構いません。

Sheet コラム
A1: 【開発者コラム】抽出ロジックの設計思想：安定と速度のバランス
A3: 本テンプレートの数式には、実務での「確実性」を最優先した設計思想が詰まっています。なぜ最新の関数や最速のロジックではなく、現在の数式を採用しているのか、その理由を解説します。
A5: 1. なぜ「SMALL関数」を採用しているのか（現在の設定）
A7: 本シートではINDEX関数とSMALL関数を組み合わせた抽出を行っています。
A9: メリット（使いやすさ）： 特別な「作業列（連番）」を自前で作る必要がなく、データを貼り付けるだけで動きます。ユーザーが数式を壊すリスクが最も低い、安定した方式です。
A11: 安定性： 32ビット版Excelなどのメモリ制限が厳しい環境でも、1行ずつ着実に処理を行うため、数万行〜数十万行の巨大データでも強制終了しにくい「タフな設計」です。
A13: 2. さらに高速化したい方へ（MATCH関数の可能性）
A15: もしあなたが数十万行のデータを扱い、コンマ数秒の計算速度すら犠牲にしたくない場合、さらに高速な「MATCH関数」による手法が存在します。
A17: 圧倒的な速さ： MATCH関数の「近似一致」を利用すれば、数万行規模のデータでも高速に検索が可能です。SMALL関数方式と比較して、行数が多いほど再計算時間に大きな差が出ます。
A19: 導入の壁： ただし、これには「抽出対象だけに1, 2, 3...と完璧な連番（シリアル番号）を振る」という高度な前処理が必要です。空白行が一つあるだけで計算が狂うため、非常に繊細な管理が求められます。
A21: 3. メモリと動作環境についてのヒント
A23: Excelには「計算の速さ」と「メモリの消費」のトレードオフがあります。
... A29: 設計者のメッセージ： > 「とにかく速いだけの道具」よりも、**「どんな環境でも、誰が使っても、確実に結果が出る道具」**であること。それが、60万行の現場を経験して辿り着いた、実務ツールの黄金比です。
