Workbook

Sheet 貼付シート
D1: ================================================================================
D2: 取引明細一覧表 出力日：2024/06/30 PAGE: 1
D3: ================================================================================
D4: 従業員CD 氏名 取引日 取引先名 金額 摘要
D5: ────────────────────────────────────────────────────────────────────────────────────
B6: =IF(C6<>"",C6,B5) -> 【001000 総務部 】 | C6: =IF(MIDB(D6,1,2)="【",D6,"") -> 【001000 総務部 】 | D6: 【001000 総務部 】
A7: =IF(MIDB(D7,4,1)="-",ROW(D7),"") -> 7 | B7: =IF(C7<>"",C7,B6) -> 【001000 総務部 】 | C7: =IF(MIDB(D7,1,2)="【",D7,"") | D7: EMP-00101 佐藤 一郎 2024/06/01 株式会社北都商事 125000 事務用品購入
A8: =IF(MIDB(D8,4,1)="-",ROW(D8),"") -> 8 | B8: =IF(C8<>"",C8,B7) -> 【001000 総務部 】 | C8: =IF(MIDB(D8,1,2)="【",D8,"") | D8: EMP-00101 佐藤 一郎 2024/06/05 有限会社南海物産 48000 消耗品補充
A9: =IF(MIDB(D9,4,1)="-",ROW(D9),"") -> 9 | B9: =IF(C9<>"",C9,B8) -> 【001000 総務部 】 | C9: =IF(MIDB(D9,1,2)="【",D9,"") | D9: EMP-00102 鈴木 花子 2024/06/03 合同会社東西サービス 72000 清掃業務委託
A10: =IF(MIDB(D10,4,1)="-",ROW(D10),"") -> 10 | B10: =IF(C10<>"",C10,B9) -> 【001000 総務部 】 | C10: =IF(MIDB(D10,1,2)="【",D10,"") | D10: EMP-00102 鈴木 花子 2024/06/10 株式会社北都商事 33500 コピー用紙発注
A11: =IF(MIDB(D11,4,1)="-",ROW(D11),"") -> 11 | B11: =IF(C11<>"",C11,B10) -> 【001000 総務部 】 | C11: =IF(MIDB(D11,1,2)="【",D11,"") | D11: EMP-00102 鈴木 花子 2024/06/18 個人事業主田中建設 185000 修繕工事代金
A12: =IF(MIDB(D12,4,1)="-",ROW(D12),"") -> 12 | B12: =IF(C12<>"",C12,B11) -> 【001000 総務部 】 | C12: =IF(MIDB(D12,1,2)="【",D12,"") | D12: EMP-00103 高橋 健太 2024/06/07 株式会社中央システム 96000 PC保守契約
A13: =IF(MIDB(D13,4,1)="-",ROW(D13),"") -> 13 | B13: =IF(C13<>"",C13,B12) -> 【001000 総務部 】 | C13: =IF(MIDB(D13,1,2)="【",D13,"") | D13: EMP-00103 高橋 健太 2024/06/12 合同会社東西サービス 15000 名刺印刷
A14: =IF(MIDB(D14,4,1)="-",ROW(D14),"") -> 14 | B14: =IF(C14<>"",C14,B13) -> 【001000 総務部 】 | C14: =IF(MIDB(D14,1,2)="【",D14,"") | D14: EMP-00103 高橋 健太 2024/06/20 有限会社南海物産 62000 備品購入
A15: =IF(MIDB(D15,4,1)="-",ROW(D15),"") | B15: =IF(C15<>"",C15,B14) -> 【001000 総務部 】 | C15: =IF(MIDB(D15,1,2)="【",D15,"") | D15: ────────────────────────────────────────────────────────────────────────────────────
A16: =IF(MIDB(D16,4,1)="-",ROW(D16),"") | B16: =IF(C16<>"",C16,B15) -> 【001000 総務部 】 | C16: =IF(MIDB(D16,1,2)="【",D16,"") | D16: 小計： 636500
A17: =IF(MIDB(D17,4,1)="-",ROW(D17),"") | B17: =IF(C17<>"",C17,B16) -> 【001000 総務部 】 | C17: =IF(MIDB(D17,1,2)="【",D17,"")
A18: =IF(MIDB(D18,4,1)="-",ROW(D18),"") | B18: =IF(C18<>"",C18,B17) -> 【001000 総務部 】 | C18: =IF(MIDB(D18,1,2)="【",D18,"") | D18: ================================================================================
A19: =IF(MIDB(D19,4,1)="-",ROW(D19),"") | B19: =IF(C19<>"",C19,B18) -> 【001000 総務部 】 | C19: =IF(MIDB(D19,1,2)="【",D19,"") | D19: 取引明細一覧表 出力日：2024/06/30 PAGE: 2
A20: =IF(MIDB(D20,4,1)="-",ROW(D20),"") | B20: =IF(C20<>"",C20,B19) -> 【001000 総務部 】 | C20: =IF(MIDB(D20,1,2)="【",D20,"") | D20: ================================================================================
A21: =IF(MIDB(D21,4,1)="-",ROW(D21),"") | B21: =IF(C21<>"",C21,B20) -> 【001000 総務部 】 | C21: =IF(MIDB(D21,1,2)="【",D21,"") | D21: 従業員CD 氏名 取引日 取引先名 金額 摘要
A22: =IF(MIDB(D22,4,1)="-",ROW(D22),"") | B22: =IF(C22<>"",C22,B21) -> 【001000 総務部 】 | C22: =IF(MIDB(D22,1,2)="【",D22,"") | D22: ────────────────────────────────────────────────────────────────────────────────────
A23: =IF(MIDB(D23,4,1)="-",ROW(D23),"") | B23: =IF(C23<>"",C23,B22) -> 【001000 総務部 】（つづき） | C23: =IF(MIDB(D23,1,2)="【",D23,"") -> 【001000 総務部 】（つづき） | D23: 【001000 総務部 】（つづき）
A24: =IF(MIDB(D24,4,1)="-",ROW(D24),"") -> 24 | B24: =IF(C24<>"",C24,B23) -> 【001000 総務部 】（つづき） | C24: =IF(MIDB(D24,1,2)="【",D24,"") | D24: EMP-00104 渡辺 美咲 2024/06/08 株式会社北都商事 27500 封筒印刷
A25: =IF(MIDB(D25,4,1)="-",ROW(D25),"") -> 25 | B25: =IF(C25<>"",C25,B24) -> 【001000 総務部 】（つづき） | C25: =IF(MIDB(D25,1,2)="【",D25,"") | D25: EMP-00104 渡辺 美咲 2024/06/15 株式会社中央システム 110000 サーバー保守
A26: =IF(MIDB(D26,4,1)="-",ROW(D26),"") -> 26 | B26: =IF(C26<>"",C26,B25) -> 【001000 総務部 】（つづき） | C26: =IF(MIDB(D26,1,2)="【",D26,"") | D26: EMP-00104 渡辺 美咲 2024/06/22 有限会社南海物産 44000 衛生用品購入
A27: =IF(MIDB(D27,4,1)="-",ROW(D27),"") -> 27 | B27: =IF(C27<>"",C27,B26) -> 【001000 総務部 】（つづき） | C27: =IF(MIDB(D27,1,2)="【",D27,"") | D27: EMP-00105 伊藤 大輔 2024/06/11 個人事業主田中建設 230000 空調設備点検
A28: =IF(MIDB(D28,4,1)="-",ROW(D28),"") -> 28 | B28: =IF(C28<>"",C28,B27) -> 【001000 総務部 】（つづき） | C28: =IF(MIDB(D28,1,2)="【",D28,"") | D28: EMP-00105 伊藤 大輔 2024/06/25 合同会社東西サービス 58000 警備業務委託
A29: =IF(MIDB(D29,4,1)="-",ROW(D29),"") -> 29 | B29: =IF(C29<>"",C29,B28) -> 【001000 総務部 】（つづき） | C29: =IF(MIDB(D29,1,2)="【",D29,"") | D29: EMP-00105 伊藤 大輔 2024/06/28 株式会社北都商事 19500 文具発注
... A31: =IF(MIDB(D31,4,1)="-",ROW(D31),"") | B31: =IF(C31<>"",C31,B30) -> 【001000 総務部 】（つづき） | C31: =IF(MIDB(D31,1,2)="【",D31,"") | D31: 小計： 489000
A32: =IF(MIDB(D32,4,1)="-",ROW(D32),"") | B32: =IF(C32<>"",C32,B31) -> 【001000 総務部 】（つづき） | C32: =IF(MIDB(D32,1,2)="【",D32,"")
A33: =IF(MIDB(D33,4,1)="-",ROW(D33),"") | B33: =IF(C33<>"",C33,B32) -> 【001000 総務部 】（つづき） | C33: =IF(MIDB(D33,1,2)="【",D33,"") | D33: ================================================================================
A34: =IF(MIDB(D34,4,1)="-",ROW(D34),"") | B34: =IF(C34<>"",C34,B33) -> 【001000 総務部 】（つづき） | C34: =IF(MIDB(D34,1,2)="【",D34,"") | D34: 取引明細一覧表 出力日：2024/06/30 PAGE: 3
A35: =IF(MIDB(D35,4,1)="-",ROW(D35),"") | B35: =IF(C35<>"",C35,B34) -> 【001000 総務部 】（つづき） | C35: =IF(MIDB(D35,1,2)="【",D35,"") | D35: ================================================================================
A36: =IF(MIDB(D36,4,1)="-",ROW(D36),"") | B36: =IF(C36<>"",C36,B35) -> 【001000 総務部 】（つづき） | C36: =IF(MIDB(D36,1,2)="【",D36,"") | D36: 従業員CD 氏名 取引日 取引先名 金額 摘要
A37: =IF(MIDB(D37,4,1)="-",ROW(D37),"") | B37: =IF(C37<>"",C37,B36) -> 【001000 総務部 】（つづき） | C37: =IF(MIDB(D37,1,2)="【",D37,"") | D37: ────────────────────────────────────────────────────────────────────────────────────
A38: =IF(MIDB(D38,4,1)="-",ROW(D38),"") | B38: =IF(C38<>"",C38,B37) -> 【002000 営業第一課 】 | C38: =IF(MIDB(D38,1,2)="【",D38,"") -> 【002000 営業第一課 】 | D38: 【002000 営業第一課 】
A39: =IF(MIDB(D39,4,1)="-",ROW(D39),"") -> 39 | B39: =IF(C39<>"",C39,B38) -> 【002000 営業第一課 】 | C39: =IF(MIDB(D39,1,2)="【",D39,"") | D39: EMP-00201 中村 翔太 2024/06/02 株式会社西日本工業 340000 製品納品代金
A40: =IF(MIDB(D40,4,1)="-",ROW(D40),"") -> 40 | B40: =IF(C40<>"",C40,B39) -> 【002000 営業第一課 】 | C40: =IF(MIDB(D40,1,2)="【",D40,"") | D40: EMP-00201 中村 翔太 2024/06/09 有限会社丸山製作所 187000 部品調達費
A41: =IF(MIDB(D41,4,1)="-",ROW(D41),"") -> 41 | B41: =IF(C41<>"",C41,B40) -> 【002000 営業第一課 】 | C41: =IF(MIDB(D41,1,2)="【",D41,"") | D41: EMP-00201 中村 翔太 2024/06/16 株式会社大和運輸 55000 配送料
...

Sheet 抽出シート
A1: 作業列１ | B1: 作業列２ | C1: 番号 | D1: 従業員CD | E1: 氏名 | F1: 取引日 | G1: 取引先名 | H1: 部署コード | I1: 部署名 | J1: 金額 | K1: 摘要
A2: {=IFERROR(INDEX(貼付シート!$D$1:$D$10000,SMALL(貼付シート!$A$1:$A$10000,C2)),"")} -> EMP-00101 佐藤 一郎 2024/06/01 株式会社北都商事 125000 事務用品購入 | B2: {=IFERROR(INDEX(貼付シート!$B$1:$B$10000,SMALL(貼付シート!$A$1:$A$10000,C2)+1),"")} -> 【001000 総務部 】 | C2: 1 | D2: =MIDB(A2,1,9) -> EMP-00101 | E2: =TRIM(MIDB(A2,11,21)) -> 佐藤 一郎 | F2: =MIDB(A2,32,10) -> 2024/06/01 | G2: =TRIM(MIDB(A2,43,37)) -> 株式会社北都商事 | H2: =MIDB(B2,2,7) -> 001000 | I2: =TRIM(MIDB(B2,10,15)) -> 総務部 | J2: =IF(A2="","",VALUE(TRIM(MIDB(A2,73,13)))) -> 125000 | K2: =TRIM(MIDB(A2,87,30)) -> 事務用品購入
A3: {=IFERROR(INDEX(貼付シート!$D$1:$D$10000,SMALL(貼付シート!$A$1:$A$10000,C3)),"")} -> EMP-00101 佐藤 一郎 2024/06/05 有限会社南海物産 48000 消耗品補充 | B3: {=IFERROR(INDEX(貼付シート!$B$1:$B$10000,SMALL(貼付シート!$A$1:$A$10000,C3)+1),"")} -> 【001000 総務部 】 | C3: 2 | D3: =MIDB(A3,1,9) -> EMP-00101 | E3: =TRIM(MIDB(A3,11,21)) -> 佐藤 一郎 | F3: =MIDB(A3,32,10) -> 2024/06/05 | G3: =TRIM(MIDB(A3,43,37)) -> 有限会社南海物産 | H3: =MIDB(B3,2,7) -> 001000 | I3: =TRIM(MIDB(B3,10,15)) -> 総務部 | J3: =IF(A3="","",VALUE(TRIM(MIDB(A3,73,13)))) -> 48000 | K3: =TRIM(MIDB(A3,87,30)) -> 消耗品補充
A4: {=IFERROR(INDEX(貼付シート!$D$1:$D$10000,SMALL(貼付シート!$A$1:$A$10000,C4)),"")} -> EMP-00102 鈴木 花子 2024/06/03 合同会社東西サービス 72000 清掃業務委託 | B4: {=IFERROR(INDEX(貼付シート!$B$1:$B$10000,SMALL(貼付シート!$A$1:$A$10000,C4)+1),"")} -> 【001000 総務部 】 | C4: 3 | D4: =MIDB(A4,1,9) -> EMP-00102 | E4: =TRIM(MIDB(A4,11,21)) -> 鈴木 花子 | F4: =MIDB(A4,32,10) -> 2024/06/03 | G4: =TRIM(MIDB(A4,43,37)) -> 合同会社東西サービス | H4: =MIDB(B4,2,7) -> 001000 | I4: =TRIM(MIDB(B4,10,15)) -> 総務部 | J4: =IF(A4="","",VALUE(TRIM(MIDB(A4,73,13)))) -> 72000 | K4: =TRIM(MIDB(A4,87,30)) -> 清掃業務委託
A5: {=IFERROR(INDEX(貼付シート!$D$1:$D$10000,SMALL(貼付シート!$A$1:$A$10000,C5)),"")} -> EMP-00102 鈴木 花子 2024/06/10 株式会社北都商事 33500 コピー用紙発注 | B5: {=IFERROR(INDEX(貼付シート!$B$1:$B$10000,SMALL(貼付シート!$A$1:$A$10000,C5)+1),"")} -> 【001000 総務部 】 | C5: 4 | D5: =MIDB(A5,1,9) -> EMP-00102 | E5: =TRIM(MIDB(A5,11,21)) -> 鈴木 花子 | F5: =MIDB(A5,32,10) -> 2024/06/10 | G5: =TRIM(MIDB(A5,43,37)) -> 株式会社北都商事 | H5: =MIDB(B5,2,7) -> 001000 | I5: =TRIM(MIDB(B5,10,15)) -> 総務部 | J5: =IF(A5="","",VALUE(TRIM(MIDB(A5,73,13)))) -> 33500 | K5: =TRIM(MIDB(A5,87,30)) -> コピー用紙発注
A6: {=IFERROR(INDEX(貼付シート!$D$1:$D$10000,SMALL(貼付シート!$A$1:$A$10000,C6)),"")} -> EMP-00102 鈴木 花子 2024/06/18 個人事業主田中建設 185000 修繕工事代金 | B6: {=IFERROR(INDEX(貼付シート!$B$1:$B$10000,SMALL(貼付シート!$A$1:$A$10000,C6)+1),"")} -> 【001000 総務部 】 | C6: 5 | D6: =MIDB(A6,1,9) -> EMP-00102 | E6: =TRIM(MIDB(A6,11,21)) -> 鈴木 花子 | F6: =MIDB(A6,32,10) -> 2024/06/18 | G6: =TRIM(MIDB(A6,43,37)) -> 個人事業主田中建設 | H6: =MIDB(B6,2,7) -> 001000 | I6: =TRIM(MIDB(B6,10,15)) -> 総務部 | J6: =IF(A6="","",VALUE(TRIM(MIDB(A6,73,13)))) -> 185000 | K6: =TRIM(MIDB(A6,87,30)) -> 修繕工事代金
A7: {=IFERROR(INDEX(貼付シート!$D$1:$D$10000,SMALL(貼付シート!$A$1:$A$10000,C7)),"")} -> EMP-00103 高橋 健太 2024/06/07 株式会社中央システム 96000 PC保守契約 | B7: {=IFERROR(INDEX(貼付シート!$B$1:$B$10000,SMALL(貼付シート!$A$1:$A$10000,C7)+1),"")} -> 【001000 総務部 】 | C7: 6 | D7: =MIDB(A7,1,9) -> EMP-00103 | E7: =TRIM(MIDB(A7,11,21)) -> 高橋 健太 | F7: =MIDB(A7,32,10) -> 2024/06/07 | G7: =TRIM(MIDB(A7,43,37)) -> 株式会社中央システム | H7: =MIDB(B7,2,7) -> 001000 | I7: =TRIM(MIDB(B7,10,15)) -> 総務部 | J7: =IF(A7="","",VALUE(TRIM(MIDB(A7,73,13)))) -> 96000 | K7: =TRIM(MIDB(A7,87,30)) -> PC保守契約
A8: {=IFERROR(INDEX(貼付シート!$D$1:$D$10000,SMALL(貼付シート!$A$1:$A$10000,C8)),"")} -> EMP-00103 高橋 健太 2024/06/12 合同会社東西サービス 15000 名刺印刷 | B8: {=IFERROR(INDEX(貼付シート!$B$1:$B$10000,SMALL(貼付シート!$A$1:$A$10000,C8)+1),"")} -> 【001000 総務部 】 | C8: 7 | D8: =MIDB(A8,1,9) -> EMP-00103 | E8: =TRIM(MIDB(A8,11,21)) -> 高橋 健太 | F8: =MIDB(A8,32,10) -> 2024/06/12 | G8: =TRIM(MIDB(A8,43,37)) -> 合同会社東西サービス | H8: =MIDB(B8,2,7) -> 001000 | I8: =TRIM(MIDB(B8,10,15)) -> 総務部 | J8: =IF(A8="","",VALUE(TRIM(MIDB(A8,73,13)))) -> 15000 | K8: =TRIM(MIDB(A8,87,30)) -> 名刺印刷
A9: {=IFERROR(INDEX(貼付シート!$D$1:$D$10000,SMALL(貼付シート!$A$1:$A$10000,C9)),"")} -> EMP-00103 高橋 健太 2024/06/20 有限会社南海物産 62000 備品購入 | B9: {=IFERROR(INDEX(貼付シート!$B$1:$B$10000,SMALL(貼付シート!$A$1:$A$10000,C9)+1),"")} -> 【001000 総務部 】 | C9: 8 | D9: =MIDB(A9,1,9) -> EMP-00103 | E9: =TRIM(MIDB(A9,11,21)) -> 高橋 健太 | F9: =MIDB(A9,32,10) -> 2024/06/20 | G9: =TRIM(MIDB(A9,43,37)) -> 有限会社南海物産 | H9: =MIDB(B9,2,7) -> 001000 | I9: =TRIM(MIDB(B9,10,15)) -> 総務部 | J9: =IF(A9="","",VALUE(TRIM(MIDB(A9,73,13)))) -> 62000 | K9: =TRIM(MIDB(A9,87,30)) -> 備品購入
A10: {=IFERROR(INDEX(貼付シート!$D$1:$D$10000,SMALL(貼付シート!$A$1:$A$10000,C10)),"")} -> EMP-00104 渡辺 美咲 2024/06/08 株式会社北都商事 27500 封筒印刷 | B10: {=IFERROR(INDEX(貼付シート!$B$1:$B$10000,SMALL(貼付シート!$A$1:$A$10000,C10)+1),"")} -> 【001000 総務部 】（つづき） | C10: 9 | D10: =MIDB(A10,1,9) -> EMP-00104 | E10: =TRIM(MIDB(A10,11,21)) -> 渡辺 美咲 | F10: =MIDB(A10,32,10) -> 2024/06/08 | G10: =TRIM(MIDB(A10,43,37)) -> 株式会社北都商事 | H10: =MIDB(B10,2,7) -> 001000 | I10: =TRIM(MIDB(B10,10,15)) -> 総務部 | J10: =IF(A10="","",VALUE(TRIM(MIDB(A10,73,13)))) -> 27500 | K10: =TRIM(MIDB(A10,87,30)) -> 封筒印刷
A11: {=IFERROR(INDEX(貼付シート!$D$1:$D$10000,SMALL(貼付シート!$A$1:$A$10000,C11)),"")} -> EMP-00104 渡辺 美咲 2024/06/15 株式会社中央システム 110000 サーバー保守 | B11: {=IFERROR(INDEX(貼付シート!$B$1:$B$10000,SMALL(貼付シート!$A$1:$A$10000,C11)+1),"")} -> 【001000 総務部 】（つづき） | C11: 10 | D11: =MIDB(A11,1,9) -> EMP-00104 | E11: =TRIM(MIDB(A11,11,21)) -> 渡辺 美咲 | F11: =MIDB(A11,32,10) -> 2024/06/15 | G11: =TRIM(MIDB(A11,43,37)) -> 株式会社中央システム | H11: =MIDB(B11,2,7) -> 001000 | I11: =TRIM(MIDB(B11,10,15)) -> 総務部 | J11: =IF(A11="","",VALUE(TRIM(MIDB(A11,73,13)))) -> 110000 | K11: =TRIM(MIDB(A11,87,30)) -> サーバー保守
A12: {=IFERROR(INDEX(貼付シート!$D$1:$D$10000,SMALL(貼付シート!$A$1:$A$10000,C12)),"")} -> EMP-00104 渡辺 美咲 2024/06/22 有限会社南海物産 44000 衛生用品購入 | B12: {=IFERROR(INDEX(貼付シート!$B$1:$B$10000,SMALL(貼付シート!$A$1:$A$10000,C12)+1),"")} -> 【001000 総務部 】（つづき） | C12: 11 | D12: =MIDB(A12,1,9) -> EMP-00104 | E12: =TRIM(MIDB(A12,11,21)) -> 渡辺 美咲 | F12: =MIDB(A12,32,10) -> 2024/06/22 | G12: =TRIM(MIDB(A12,43,37)) -> 有限会社南海物産 | H12: =MIDB(B12,2,7) -> 001000 | I12: =TRIM(MIDB(B12,10,15)) -> 総務部 | J12: =IF(A12="","",VALUE(TRIM(MIDB(A12,73,13)))) -> 44000 | K12: =TRIM(MIDB(A12,87,30)) -> 衛生用品購入
A13: {=IFERROR(INDEX(貼付シート!$D$1:$D$10000,SMALL(貼付シート!$A$1:$A$10000,C13)),"")} -> EMP-00105 伊藤 大輔 2024/06/11 個人事業主田中建設 230000 空調設備点検 | B13: {=IFERROR(INDEX(貼付シート!$B$1:$B$10000,SMALL(貼付シート!$A$1:$A$10000,C13)+1),"")} -> 【001000 総務部 】（つづき） | C13: 12 | D13: =MIDB(A13,1,9) -> EMP-00105 | E13: =TRIM(MIDB(A13,11,21)) -> 伊藤 大輔 | F13: =MIDB(A13,32,10) -> 2024/06/11 | G13: =TRIM(MIDB(A13,43,37)) -> 個人事業主田中建設 | H13: =MIDB(B13,2,7) -> 001000 | I13: =TRIM(MIDB(B13,10,15)) -> 総務部 | J13: =IF(A13="","",VALUE(TRIM(MIDB(A13,73,13)))) -> 230000 | K13: =TRIM(MIDB(A13,87,30)) -> 空調設備点検
... A101: {=IFERROR(INDEX(貼付シート!$D$1:$D$10000,SMALL(貼付シート!$A$1:$A$10000,C101)),"")} | B101: {=IFERROR(INDEX(貼付シート!$B$1:$B$10000,SMALL(貼付シート!$A$1:$A$10000,C101)+1),"")} | C101: 100 | D101: =MIDB(A101,1,9) | E101: =TRIM(MIDB(A101,11,21)) | F101: =MIDB(A101,32,10) | G101: =TRIM(MIDB(A101,43,37)) | H101: =MIDB(B101,2,7) | I101: =TRIM(MIDB(B101,10,15)) | J101: =IF(A101="","",VALUE(TRIM(MIDB(A101,73,13)))) | K101: =TRIM(MIDB(A101,87,30))

Sheet 手順書
A1: 固定長テキスト整形テンプレート③（親情報フィルダウン＝引き継ぎ編） ― カスタマイズ手順書
A4: ■ このテンプレートのテーマ
A6: このテンプレートは「引き継ぎ（フィルダウン）」に特化したテンプレートです。
A7: 帳票の中で1回だけ印字される親情報（部署名・会社名・支店名など）を
A8: すべてのデータ行に自動で補完する仕組みを学ぶことが目的です。
A10: テンプレート①（不要行除去＋MIDB切り出し）と
A11: テンプレート②（複数行→1行結合）で学んだ技法に、
A12: この③の引き継ぎ（フィルダウン）を組み合わせれば、
A13: 親情報の補完＋不要行除去＋複数行結合を同時に処理でき、
A14: 実務で遭遇する固定長帳票の大半のパターンに対応できます。
A17: ■ このテンプレートの仕組み
A19: 処理の流れ
... A161: 【B列：フィルダウン】
A162: =IF(C2<>"",C2,B1) -> 0
A163: この数式は通常変更不要です。
A164: C列の検出が正しければ自動的に正しくフィルダウンされます。
A166: 【A列：データ行の判定】
A167: 以下の文字列で不要行を除外しています。
A168: 「====」 → 区切り線
A169: 「────」 → 罫線
A170: 「取引明細」→ ページヘッダー
A171: 「従業員CD」→ 列見出し
A172: 「【」 → 部署名行（親情報行自体はデータ行ではない）
A173: 「小計：」 → 小計行
A174: 「合計：」 → 合計行
A175: 「PAGE:」 → ページフッター
... A316: ご自身の環境に合わせて置き換えていただいても構いません。
